[2023-12-07 08:46:30,211] torch.distributed.run: [WARNING] 
[2023-12-07 08:46:30,211] torch.distributed.run: [WARNING] *****************************************
[2023-12-07 08:46:30,211] torch.distributed.run: [WARNING] Setting OMP_NUM_THREADS environment variable for each process to be 1 in default, to avoid your system being overloaded, please further tune the variable for optimal performance in your application as needed. 
[2023-12-07 08:46:30,211] torch.distributed.run: [WARNING] *****************************************
Detected kernel version 4.18.0, which is below the recommended minimum of 5.5.0; this can cause the process to hang. It is recommended to upgrade the kernel to the minimum version or higher.
Traceback (most recent call last):
Traceback (most recent call last):
  File "finetune.py", line 21, in <module>
  File "finetune.py", line 21, in <module>
    accelerator = Accelerator()
  File "/scratch/jd5226/hpml/lib/python3.8/site-packages/accelerate/accelerator.py", line 371, in __init__
Traceback (most recent call last):
  File "finetune.py", line 21, in <module>
    accelerator = Accelerator()
  File "/scratch/jd5226/hpml/lib/python3.8/site-packages/accelerate/accelerator.py", line 371, in __init__
    accelerator = Accelerator()
  File "/scratch/jd5226/hpml/lib/python3.8/site-packages/accelerate/accelerator.py", line 371, in __init__
Traceback (most recent call last):
  File "finetune.py", line 21, in <module>
    accelerator = Accelerator()
  File "/scratch/jd5226/hpml/lib/python3.8/site-packages/accelerate/accelerator.py", line 371, in __init__
        self.state = AcceleratorState(        self.state = AcceleratorState(
self.state = AcceleratorState(self.state = AcceleratorState(
  File "/scratch/jd5226/hpml/lib/python3.8/site-packages/accelerate/state.py", line 758, in __init__


  File "/scratch/jd5226/hpml/lib/python3.8/site-packages/accelerate/state.py", line 758, in __init__
  File "/scratch/jd5226/hpml/lib/python3.8/site-packages/accelerate/state.py", line 758, in __init__
  File "/scratch/jd5226/hpml/lib/python3.8/site-packages/accelerate/state.py", line 758, in __init__
    PartialState(cpu, **kwargs)    
    PartialState(cpu, **kwargs)      File "/scratch/jd5226/hpml/lib/python3.8/site-packages/accelerate/state.py", line 230, in __init__
PartialState(cpu, **kwargs)
PartialState(cpu, **kwargs)
  File "/scratch/jd5226/hpml/lib/python3.8/site-packages/accelerate/state.py", line 230, in __init__

  File "/scratch/jd5226/hpml/lib/python3.8/site-packages/accelerate/state.py", line 230, in __init__
  File "/scratch/jd5226/hpml/lib/python3.8/site-packages/accelerate/state.py", line 230, in __init__
    torch.cuda.set_device(self.device)
  File "/scratch/jd5226/hpml/lib/python3.8/site-packages/torch/cuda/__init__.py", line 404, in set_device
        torch.cuda.set_device(self.device)torch.cuda.set_device(self.device)    

torch.cuda.set_device(self.device)  File "/scratch/jd5226/hpml/lib/python3.8/site-packages/torch/cuda/__init__.py", line 404, in set_device
  File "/scratch/jd5226/hpml/lib/python3.8/site-packages/torch/cuda/__init__.py", line 404, in set_device

  File "/scratch/jd5226/hpml/lib/python3.8/site-packages/torch/cuda/__init__.py", line 404, in set_device
    torch._C._cuda_setDevice(device)
RuntimeError: CUDA error: invalid device ordinal
CUDA kernel errors might be asynchronously reported at some other API call, so the stacktrace below might be incorrect.
For debugging consider passing CUDA_LAUNCH_BLOCKING=1.
Compile with `TORCH_USE_CUDA_DSA` to enable device-side assertions.

        torch._C._cuda_setDevice(device)torch._C._cuda_setDevice(device)    

torch._C._cuda_setDevice(device)RuntimeError
RuntimeError: : RuntimeErrorCUDA error: invalid device ordinal
CUDA kernel errors might be asynchronously reported at some other API call, so the stacktrace below might be incorrect.
For debugging consider passing CUDA_LAUNCH_BLOCKING=1.
Compile with `TORCH_USE_CUDA_DSA` to enable device-side assertions.
CUDA error: invalid device ordinal
CUDA kernel errors might be asynchronously reported at some other API call, so the stacktrace below might be incorrect.
For debugging consider passing CUDA_LAUNCH_BLOCKING=1.
Compile with `TORCH_USE_CUDA_DSA` to enable device-side assertions.

: 
CUDA error: invalid device ordinal
CUDA kernel errors might be asynchronously reported at some other API call, so the stacktrace below might be incorrect.
For debugging consider passing CUDA_LAUNCH_BLOCKING=1.
Compile with `TORCH_USE_CUDA_DSA` to enable device-side assertions.

Loading checkpoint shards:   0%|          | 0/2 [00:00<?, ?it/s]Loading checkpoint shards:   0%|          | 0/2 [00:00<?, ?it/s]Loading checkpoint shards:   0%|          | 0/2 [00:00<?, ?it/s]Loading checkpoint shards:   0%|          | 0/2 [00:00<?, ?it/s][2023-12-07 08:47:00,328] torch.distributed.elastic.multiprocessing.api: [WARNING] Sending process 2213906 closing signal SIGTERM
[2023-12-07 08:47:00,328] torch.distributed.elastic.multiprocessing.api: [WARNING] Sending process 2213907 closing signal SIGTERM
[2023-12-07 08:47:00,328] torch.distributed.elastic.multiprocessing.api: [WARNING] Sending process 2213908 closing signal SIGTERM
[2023-12-07 08:47:00,328] torch.distributed.elastic.multiprocessing.api: [WARNING] Sending process 2213909 closing signal SIGTERM
[2023-12-07 08:47:00,410] torch.distributed.elastic.multiprocessing.api: [ERROR] failed (exitcode: 1) local_rank: 4 (pid: 2213910) of binary: /scratch/jd5226/hpml/bin/python3.8
Traceback (most recent call last):
  File "/scratch/jd5226/hpml/bin/torchrun", line 8, in <module>
    sys.exit(main())
  File "/scratch/jd5226/hpml/lib/python3.8/site-packages/torch/distributed/elastic/multiprocessing/errors/__init__.py", line 346, in wrapper
    return f(*args, **kwargs)
  File "/scratch/jd5226/hpml/lib/python3.8/site-packages/torch/distributed/run.py", line 806, in main
    run(args)
  File "/scratch/jd5226/hpml/lib/python3.8/site-packages/torch/distributed/run.py", line 797, in run
    elastic_launch(
  File "/scratch/jd5226/hpml/lib/python3.8/site-packages/torch/distributed/launcher/api.py", line 134, in __call__
    return launch_agent(self._config, self._entrypoint, list(args))
  File "/scratch/jd5226/hpml/lib/python3.8/site-packages/torch/distributed/launcher/api.py", line 264, in launch_agent
    raise ChildFailedError(
torch.distributed.elastic.multiprocessing.errors.ChildFailedError: 
============================================================
finetune.py FAILED
------------------------------------------------------------
Failures:
[1]:
  time      : 2023-12-07_08:47:00
  host      : gr033.hpc.nyu.edu
  rank      : 5 (local_rank: 5)
  exitcode  : 1 (pid: 2213911)
  error_file: <N/A>
  traceback : To enable traceback see: https://pytorch.org/docs/stable/elastic/errors.html
[2]:
  time      : 2023-12-07_08:47:00
  host      : gr033.hpc.nyu.edu
  rank      : 6 (local_rank: 6)
  exitcode  : 1 (pid: 2213913)
  error_file: <N/A>
  traceback : To enable traceback see: https://pytorch.org/docs/stable/elastic/errors.html
[3]:
  time      : 2023-12-07_08:47:00
  host      : gr033.hpc.nyu.edu
  rank      : 7 (local_rank: 7)
  exitcode  : 1 (pid: 2213915)
  error_file: <N/A>
  traceback : To enable traceback see: https://pytorch.org/docs/stable/elastic/errors.html
------------------------------------------------------------
Root Cause (first observed failure):
[0]:
  time      : 2023-12-07_08:47:00
  host      : gr033.hpc.nyu.edu
  rank      : 4 (local_rank: 4)
  exitcode  : 1 (pid: 2213910)
  error_file: <N/A>
  traceback : To enable traceback see: https://pytorch.org/docs/stable/elastic/errors.html
============================================================
